Workbook
Name Slicer_category: #N/A
Name Slicer_location: #N/A
Name Slicer_Nursery_Name: #N/A
Name Slicer_plant_name: #N/A

Sheet Nursery_Inventory
A1: Inventory_ID | B1: Plant_ID | C1: Stock_Quantity | D1: Nursery | E1: location
A2: 2001 | B2: 1104 | C2: 194 | D2: NatureNest | E2: Bangalore
A3: 2002 | B3: 1422 | C3: 245 | D3: PlantHub | E3: Pune
A4: 2003 | B4: 1384 | C4: 26 | D4: GreenGrow | E4: Mumbai
A5: 2004 | B5: 1373 | C5: 459 | D5: GreenGrow | E5: Bangalore
A6: 2005 | B6: 1405 | C6: 91 | D6: GreenGrow | E6: Delhi
A7: 2006 | B7: 1427 | C7: 428 | D7: PlantHub | E7: Bangalore
A8: 2007 | B8: 1065 | C8: 131 | D8: NatureNest | E8: Bangalore
A9: 2008 | B9: 1437 | C9: 347 | D9: EcoGarden | E9: Pune
A10: 2009 | B10: 1424 | C10: 423 | D10: NatureNest | E10: Pune
A11: 2010 | B11: 1473 | C11: 374 | D11: PlantHub | E11: Delhi
A12: 2011 | B12: 1234 | C12: 358 | D12: EcoGarden | E12: Pune
A13: 2012 | B13: 1244 | C13: 339 | D13: GreenGrow | E13: Pune
... A501: 2500 | B501: 1329 | C501: 69 | D501: GreenGrow | E501: Mumbai

Sheet Plant_Master
A1: Plant_ID | B1: Plant_Name | C1: Category | D1: Water_Need | E1: Sunlight
A2: 1001 | B2: Bamboo | C2: Indoor | D2: High | E2: Partial Sun
A3: 1002 | B3: Tulip | C3: Flower | D3: Medium | E3: Partial Sun
A4: 1003 | B4: Rose | C4: Indoor | D4: Low | E4: Shade
A5: 1004 | B5: Cactus | C5: Outdoor | D5: High | E5: Partial Sun
A6: 1005 | B6: Rose | C6: Succulent | D6: High | E6: Shade
A7: 1006 | B7: Bamboo | C7: Succulent | D7: Low | E7: Full Sun
A8: 1007 | B8: Fern | C8: Indoor | D8: Low | E8: Shade
A9: 1008 | B9: Tulip | C9: Outdoor | D9: Medium | E9: Full Sun
A10: 1009 | B10: Jasmine | C10: Succulent | D10: High | E10: Full Sun
A11: 1010 | B11: Aloe | C11: Medicinal | D11: High | E11: Shade
A12: 1011 | B12: Fern | C12: Outdoor | D12: Medium | E12: Full Sun
A13: 1012 | B13: Palm | C13: Flower | D13: High | E13: Partial Sun
... A501: 1500 | B501: Tulip | C501: Medicinal | D501: Medium | E501: Shade

Sheet NURSERY'S REVENUE
A3: Row Labels | B3: Sum of maximum revenue
A4: EcoGarden | B4: 625442
A5: GreenGrow | B5: 489861
A6: NatureNest | B6: 838135
A7: PlantHub | B7: 728345
A8: UrbanLeaf | B8: 654053
A9: Grand Total | B9: 3335836

Sheet PLANTS REVENUE
A3: Row Labels | B3: Sum of maximum revenue
A4: Aloe | B4: 291417
A5: Bamboo | B5: 271419
A6: Cactus | B6: 390691
A7: Fern | B7: 343544
A8: Jasmine | B8: 469597
A9: Lily | B9: 398092
A10: Orchid | B10: 266832
A11: Palm | B11: 183843
A12: Rose | B12: 334006
A13: Tulip | B13: 386395
A14: Grand Total | B14: 3335836

Sheet QUANTITY OF PLANTS
A3: Row Labels | B3: Count of stock quantity
A4: Aloe | B4: 52 | D4: Jasmine | E4: 59
A5: Bamboo | B5: 53 | D5: Cactus | E5: 57
A6: Cactus | B6: 57 | D6: Lily | E6: 54
A7: Fern | B7: 48 | D7: Rose | E7: 54
A8: Jasmine | B8: 59 | D8: Bamboo | E8: 53
A9: Lily | B9: 54 | D9: Aloe | E9: 52
A10: Orchid | B10: 38 | D10: Tulip | E10: 51
A11: Palm | B11: 34 | D11: Fern | E11: 48
A12: Rose | B12: 54 | D12: Orchid | E12: 38
A13: Tulip | B13: 51 | D13: Palm | E13: 34
A14: Grand Total | B14: 500

Sheet Sheet2

Sheet LOCATION WISE PLANTS
A1: Count of stock quantity | B1: Column Labels
A2: Row Labels | B2: Aloe | C2: Bamboo | D2: Cactus | E2: Fern | F2: Jasmine | G2: Lily | H2: Orchid | I2: Palm | J2: Rose | K2: Tulip | L2: Grand Total
A3: Bangalore | B3: 11 | C3: 3 | D3: 3 | E3: 4 | F3: 7 | G3: 7 | H3: 5 | I3: 5 | J3: 3 | L3: 48
A4: Chennai | B4: 7 | C4: 5 | D4: 6 | E4: 2 | F4: 9 | G4: 9 | H4: 5 | I4: 6 | J4: 7 | K4: 3 | L4: 59
A5: Delhi | B5: 12 | C5: 7 | D5: 7 | E5: 7 | F5: 4 | G5: 14 | H5: 6 | I5: 1 | J5: 9 | K5: 10 | L5: 77
A6: Mumbai | B6: 8 | C6: 3 | D6: 5 | E6: 4 | F6: 9 | G6: 5 | H6: 4 | I6: 8 | J6: 3 | K6: 8 | L6: 57
A7: Pune | B7: 1 | C7: 11 | D7: 7 | E7: 15 | F7: 6 | G7: 4 | H7: 8 | I7: 6 | J7: 9 | K7: 12 | L7: 79
A8: ROI | B8: 13 | C8: 24 | D8: 29 | E8: 16 | F8: 24 | G8: 15 | H8: 10 | I8: 8 | J8: 23 | K8: 18 | L8: 180
A9: Grand Total | B9: 52 | C9: 53 | D9: 57 | E9: 48 | F9: 59 | G9: 54 | H9: 38 | I9: 34 | J9: 54 | K9: 51 | L9: 500

Sheet UNITS SOLD BY NURSERY
A3: Row Labels | B3: Sum of Units_Sold | G3: Row Labels | H3: Sum of Sale_ID
A4: EcoGarden | B4: 0.20064623 | G4: 16 | H4: 6492
A5: GreenGrow | B5: 0.14201277 | G5: 18 | H5: 3404
A6: NatureNest | B6: 0.22570731 | G6: 19 | H6: 3021
A7: PlantHub | B7: 0.23421861 | G7: 20 | H7: 3468
A8: UrbanLeaf | B8: 0.19741508 | G8: 23 | H8: 9907
A9: Grand Total | B9: 1 | G9: 26 | H9: 6648
G10: 28 | H10: 3322
G11: 29 | H11: 3183
G12: 34 | H12: 6764
G13: 36 | H13: 6390
G14: 38 | H14: 6950
G15: 42 | H15: 16268
G16: 45 | H16: 6535
G17: 48 | H17: 9831
G18: 50 | H18: 6275
G19: 59 | H19: 9752
G20: 62 | H20: 9761
G21: 65 | H21: 6472
... G165: 499 | H165: 6558
G166: NA | H166: 584920
G167: Grand Total | H167: 1625250
H169: =GETPIVOTDATA("Sale_ID",$G$3)-GETPIVOTDATA("Sale_ID",$G$3,"stock quantity","NA") -> 1040330

Sheet NURSERY WISE PLANTS
A3: Count of Plant_ID | B3: Column Labels
A4: Row Labels | B4: Aloe | C4: Bamboo | D4: Cactus | E4: Fern | F4: Jasmine | G4: Lily | H4: Orchid | I4: Palm | J4: Rose | K4: Tulip | L4: Grand Total
A5: EcoGarden | B5: 12 | C5: 10 | D5: 11 | E5: 7 | F5: 14 | G5: 8 | H5: 5 | I5: 8 | J5: 12 | K5: 11 | L5: 98
A6: GreenGrow | B6: 8 | C6: 9 | D6: 14 | E6: 7 | F6: 9 | G6: 11 | H6: 2 | I6: 6 | J6: 7 | K6: 4 | L6: 77
A7: NatureNest | B7: 7 | C7: 12 | D7: 9 | E7: 19 | F7: 8 | G7: 10 | H7: 14 | I7: 5 | J7: 14 | K7: 17 | L7: 115
A8: PlantHub | B8: 9 | C8: 13 | D8: 14 | E8: 7 | F8: 13 | G8: 14 | H8: 10 | I8: 6 | J8: 9 | K8: 11 | L8: 106
A9: UrbanLeaf | B9: 16 | C9: 9 | D9: 9 | E9: 8 | F9: 15 | G9: 11 | H9: 7 | I9: 9 | J9: 12 | K9: 8 | L9: 104
A10: Grand Total | B10: 52 | C10: 53 | D10: 57 | E10: 48 | F10: 59 | G10: 54 | H10: 38 | I10: 34 | J10: 54 | K10: 51 | L10: 500

Sheet CATAGORY WISE PLANTS
A1: Count of Plant_ID | B1: Column Labels
A2: Row Labels | B2: Aloe | C2: Bamboo | D2: Cactus | E2: Fern | F2: Jasmine | G2: Lily | H2: Orchid | I2: Palm | J2: Rose | K2: Tulip | L2: Grand Total
A3: Flower | B3: 7 | C3: 2 | D3: 15 | E3: 13 | F3: 14 | G3: 15 | H3: 9 | I3: 8 | J3: 11 | K3: 10 | L3: 104
A4: Indoor | B4: 2 | C4: 8 | D4: 8 | E4: 8 | F4: 4 | G4: 6 | H4: 7 | J4: 16 | K4: 11 | L4: 70
A5: Medicinal | B5: 11 | C5: 18 | D5: 20 | E5: 13 | F5: 14 | G5: 11 | H5: 6 | I5: 12 | J5: 11 | K5: 11 | L5: 127
A6: Outdoor | B6: 15 | C6: 12 | D6: 6 | E6: 10 | F6: 14 | G6: 10 | H6: 6 | I6: 8 | J6: 10 | K6: 6 | L6: 97
A7: Succulent | B7: 17 | C7: 13 | D7: 8 | E7: 4 | F7: 13 | G7: 12 | H7: 10 | I7: 6 | J7: 6 | K7: 13 | L7: 102
A8: Grand Total | B8: 52 | C8: 53 | D8: 57 | E8: 48 | F8: 59 | G8: 54 | H8: 38 | I8: 34 | J8: 54 | K8: 51 | L8: 500

Sheet CATAGORY WISE REVENUE
A3: Row Labels | B3: Sum of maximum revenue
A4: Flower | B4: 0.2193678
A5: Indoor | B5: 0.14738225
A6: Medicinal | B6: 0.24668239
A7: Outdoor | B7: 0.18978571
A8: Succulent | B8: 0.19678186
A9: Grand Total | B9: 1

Sheet KPI
A3: Row Labels | B3: Sum of Units_Sold | D3: Row Labels | E3: Sum of maximum revenue | G3: Row Labels | H3: Count of Plant_ID | J3: Row Labels | K3: Average of maximum revenue | M3: Row Labels | N3: Sum of maximum revenue
A4: 1003 | B4: 37 | D4: EcoGarden | E4: 625442 | G4: Aloe | H4: 52 | J4: 1003 | K4: 9694 | M4: Jasmine | N4: 469597
A5: 1006 | B5: 68 | D5: GreenGrow | E5: 489861 | G5: Bamboo | H5: 53 | J5: 1006 | K5: 8306 | M5: Lily | N5: 398092
A6: 1007 | B6: 29 | D6: NatureNest | E6: 838135 | G6: Cactus | H6: 57 | J6: 1007 | K6: 2465 | M6: Cactus | N6: 390691
A7: 1009 | B7: 17 | D7: PlantHub | E7: 728345 | G7: Fern | H7: 48 | J7: 1009 | K7: 4505 | M7: Tulip | N7: 386395
A8: 1011 | B8: 14 | D8: UrbanLeaf | E8: 654053 | G8: Jasmine | H8: 59 | J8: 1011 | K8: 3248 | M8: Fern | N8: 343544
A9: 1012 | B9: 50 | D9: Grand Total | E9: 3335836 | G9: Lily | H9: 54 | J9: 1012 | K9: 7558 | M9: Rose | N9: 334006
A10: 1015 | B10: 1 | G10: Orchid | H10: 38 | J10: 1015 | K10: 482 | M10: Aloe | N10: 291417
A11: 1018 | B11: 85 | E11: =GETPIVOTDATA("maximum revenue",$D$3) -> 3335836 | G11: Palm | H11: 34 | J11: 1018 | K11: 7708 | M11: Bamboo | N11: 271419
A12: 1020 | B12: 35 | G12: Rose | H12: 54 | J12: 1020 | K12: 16905 | M12: Orchid | N12: 266832
A13: 1022 | B13: 50 | G13: Tulip | H13: 51 | J13: 1022 | K13: 22050 | M13: Palm | N13: 183843
A14: 1023 | B14: 75 | G14: Grand Total | H14: 500 | J14: 1023 | K14: 16537.5 | M14: Grand Total | N14: 3335836
A15: 1024 | B15: 91 | J15: 1024 | K15: 7373.3333
A16: 1025 | B16: 45 | H16: =GETPIVOTDATA("Plant_ID",$G$3) -> 500 | J16: 1025 | K16: 5102.5
A17: 1029 | B17: 10 | J17: 1029 | K17: 1810
A18: 1030 | B18: 41 | J18: 1030 | K18: 7626
A19: 1031 | B19: 13 | J19: 1031 | K19: 3718
A20: 1032 | B20: 67 | J20: 1032 | K20: 3323
A21: 1034 | B21: 44 | J21: 1034 | K21: 2798
A22: 1035 | B22: 36 | J22: 1035 | K22: 2268
A23: 1037 | B23: 100 | J23: 1037 | K23: 5014.3333
A24: 1040 | B24: 16 | J24: 1040 | K24: 6272
A25: 1041 | B25: 18 | J25: 1041 | K25: 6012
A26: 1042 | B26: 66 | J26: 1042 | K26: 5100
A27: 1044 | B27: 59 | J27: 1044 | K27: 14178
A28: 1045 | B28: 76 | J28: 1045 | K28: 8600.6667
... A323: 1500 | B323: 22 | J323: 1500 | K323: 3649
A324: Grand Total | B324: 12689 | J324: Grand Total | K324: 6671.672
B326: =GETPIVOTDATA("Units_Sold",$A$3) -> 12689 | K326: =GETPIVOTDATA("maximum revenue",$J$3) -> 6671.672

Sheet REVENUE BY NURSERY & PLANTS
A3: Row Labels | B3: Sum of maximum revenue
A4: NatureNest | B4: 838135 | I4: Sum of maximum revenue
A5: PlantHub | B5: 728345 | H5: Jasmine | I5: 469597 | K5: Jasmine | L5: 469597
A6: UrbanLeaf | B6: 654053 | H6: Lily | I6: 398092 | K6: Lily | L6: 398092
A7: EcoGarden | B7: 625442 | H7: Cactus | I7: 390691 | K7: Cactus | L7: 390691
A8: GreenGrow | B8: 489861 | H8: Tulip | I8: 386395 | K8: Tulip | L8: 386395
A9: Grand Total | B9: 3335836 | H9: Fern | I9: 343544 | K9: Fern | L9: 343544
H10: Rose | I10: 334006 | K10: Rose | L10: 334006
H11: Aloe | I11: 291417 | K11: Aloe | L11: 291417
H12: Bamboo | I12: 271419 | K12: Bamboo | L12: 271419
H13: Orchid | I13: 266832 | K13: Orchid | L13: 266832
H14: Palm | I14: 183843 | K14: Palm | L14: 183843
H15: Grand Total | I15: 3335836

Sheet INSIGHTS
M6: eco garden | N6: 625442
G7: Insights | M7: green grow | N7: 489861
M8: plant hub | N8: 728177
G9: 1.City with maximum revenue in GreenGrow nursery is | H9: CHENNAI | M9: urban leaf | N9: 629138
G11: 2.Nursery generating highest total revenue is | H11: NATURENEST
G13: 3. Plant in Medicinal category generating maximum revenue is | H13: CACTUS
G15: 4. Plant generating maximum revenue for NatureNest is from category | H15: FLOWER
G17: 5.Plant from urbanleaf nursery and indoor catagory selling maximum units is | H17: BAMBOO
G19: 6. city having largest stock quantity of plant under Medicinal category | H19: MUMBAI (4455 Plants)
G21: 7. Plant from outdoor category sold maximum units with location | H21: ORCHID (PUNE)
G23: 8. Ecogarden nursery have maximum stock quantity of plants in succulent category in | H23: MUMBAI
G25: 9. Plant from Chennai city generating maximum revenue is | H25: LILY
G27: 10.PlantHub nursery in Bangalore have maximum stock quantity of Plant | H27: ALOE

Sheet CATAGORY WISE SALE
A3: Row Labels | B3: Sum of maximum revenue
A4: Medicinal | B4: 822892 | E4: Row Labels | F4: Sum of Units_Sold
A5: Flower | B5: 731775 | E5: Flower | F5: 0.21325558
A6: Succulent | B6: 656432 | E6: Indoor | F6: 0.15013003
A7: Outdoor | B7: 633094 | E7: Medicinal | F7: 0.2499803
A8: Indoor | B8: 491643 | E8: Outdoor | F8: 0.18322957
A9: Grand Total | B9: 3335836 | E9: Succulent | F9: 0.20340452
E10: Grand Total | F10: 1

Sheet Plant_Sales
A1: Sale_ID | B1: Plant_ID | C1: Nursery_Name | D1: Units_Sold | E1: Price_per_Unit | F1: maximum revenue | G1: location | H1: plant name | I1: category | J1: stock quantity
A2: 3094 | B2: 1241 | C2: NatureNest | D2: 5 | E2: 359 | F2: =D2*E2 -> 1795 | G2: =_xlfn.XLOOKUP(B2,Nursery_Inventory!B:B,Nursery_Inventory!E:E) -> Pune | H2: =_xlfn.XLOOKUP(B2,Plant_Master!A:A,Plant_Master!B:B) -> Cactus | I2: =_xlfn.XLOOKUP(B2,Plant_Master!A:A,Plant_Master!C:C) -> Outdoor | J2: =_xlfn.XLOOKUP(B2,Nursery_Inventory!B:B,Nursery_Inventory!C:C) -> 464
A3: 3309 | B3: 1359 | C3: NatureNest | D3: 50 | E3: 480 | F3: =D3*E3 -> 24000 | G3: ROI | H3: =_xlfn.XLOOKUP(B3,Plant_Master!A:A,Plant_Master!B:B) -> Cactus | I3: =_xlfn.XLOOKUP(B3,Plant_Master!A:A,Plant_Master!C:C) -> Flower | J3: NA
A4: 3368 | B4: 1224 | C4: EcoGarden | D4: 49 | E4: 477 | F4: =D4*E4 -> 23373 | G4: =_xlfn.XLOOKUP(B4,Nursery_Inventory!B:B,Nursery_Inventory!E:E) -> Mumbai | H4: =_xlfn.XLOOKUP(B4,Plant_Master!A:A,Plant_Master!B:B) -> Cactus | I4: =_xlfn.XLOOKUP(B4,Plant_Master!A:A,Plant_Master!C:C) -> Medicinal | J4: =_xlfn.XLOOKUP(B4,Nursery_Inventory!B:B,Nursery_Inventory!C:C) -> 250
A5: 3329 | B5: 1379 | C5: UrbanLeaf | D5: 49 | E5: 500 | F5: =D5*E5 -> 24500 | G5: =_xlfn.XLOOKUP(B5,Nursery_Inventory!B:B,Nursery_Inventory!E:E) -> Bangalore | H5: =_xlfn.XLOOKUP(B5,Plant_Master!A:A,Plant_Master!B:B) -> Orchid | I5: =_xlfn.XLOOKUP(B5,Plant_Master!A:A,Plant_Master!C:C) -> Outdoor | J5: =_xlfn.XLOOKUP(B5,Nursery_Inventory!B:B,Nursery_Inventory!C:C) -> 36
A6: 3277 | B6: 1418 | C6: GreenGrow | D6: 45 | E6: 494 | F6: =D6*E6 -> 22230 | G6: =_xlfn.XLOOKUP(B6,Nursery_Inventory!B:B,Nursery_Inventory!E:E) -> Chennai | H6: =_xlfn.XLOOKUP(B6,Plant_Master!A:A,Plant_Master!B:B) -> Lily | I6: =_xlfn.XLOOKUP(B6,Plant_Master!A:A,Plant_Master!C:C) -> Medicinal | J6: =_xlfn.XLOOKUP(B6,Nursery_Inventory!B:B,Nursery_Inventory!C:C) -> 453
A7: 3228 | B7: 1412 | C7: GreenGrow | D7: 44 | E7: 435 | F7: =D7*E7 -> 19140 | G7: ROI | H7: =_xlfn.XLOOKUP(B7,Plant_Master!A:A,Plant_Master!B:B) -> Fern | I7: =_xlfn.XLOOKUP(B7,Plant_Master!A:A,Plant_Master!C:C) -> Flower | J7: NA
A8: 3154 | B8: 1022 | C8: PlantHub | D8: 50 | E8: 441 | F8: =D8*E8 -> 22050 | G8: ROI | H8: =_xlfn.XLOOKUP(B8,Plant_Master!A:A,Plant_Master!B:B) -> Jasmine | I8: =_xlfn.XLOOKUP(B8,Plant_Master!A:A,Plant_Master!C:C) -> Indoor | J8: NA
A9: 3030 | B9: 1438 | C9: EcoGarden | D9: 44 | E9: 483 | F9: =D9*E9 -> 21252 | G9: ROI | H9: =_xlfn.XLOOKUP(B9,Plant_Master!A:A,Plant_Master!B:B) -> Cactus | I9: =_xlfn.XLOOKUP(B9,Plant_Master!A:A,Plant_Master!C:C) -> Medicinal | J9: NA
A10: 3011 | B10: 1060 | C10: PlantHub | D10: 50 | E10: 271 | F10: =D10*E10 -> 13550 | G10: =_xlfn.XLOOKUP(B10,Nursery_Inventory!B:B,Nursery_Inventory!E:E) -> Chennai | H10: =_xlfn.XLOOKUP(B10,Plant_Master!A:A,Plant_Master!B:B) -> Bamboo | I10: =_xlfn.XLOOKUP(B10,Plant_Master!A:A,Plant_Master!C:C) -> Outdoor | J10: =_xlfn.XLOOKUP(B10,Nursery_Inventory!B:B,Nursery_Inventory!C:C) -> 93
A11: 3299 | B11: 1444 | C11: NatureNest | D11: 44 | E11: 426 | F11: =D11*E11 -> 18744 | G11: =_xlfn.XLOOKUP(B11,Nursery_Inventory!B:B,Nursery_Inventory!E:E) -> Delhi | H11: =_xlfn.XLOOKUP(B11,Plant_Master!A:A,Plant_Master!B:B) -> Tulip | I11: =_xlfn.XLOOKUP(B11,Plant_Master!A:A,Plant_Master!C:C) -> Indoor | J11: =_xlfn.XLOOKUP(B11,Nursery_Inventory!B:B,Nursery_Inventory!C:C) -> 499
A12: 3252 | B12: 1407 | C12: NatureNest | D12: 29 | E12: 391 | F12: =D12*E12 -> 11339 | G12: =_xlfn.XLOOKUP(B12,Nursery_Inventory!B:B,Nursery_Inventory!E:E) -> Pune | H12: =_xlfn.XLOOKUP(B12,Plant_Master!A:A,Plant_Master!B:B) -> Palm | I12: =_xlfn.XLOOKUP(B12,Plant_Master!A:A,Plant_Master!C:C) -> Flower | J12: =_xlfn.XLOOKUP(B12,Nursery_Inventory!B:B,Nursery_Inventory!C:C) -> 463
A13: 3259 | B13: 1444 | C13: UrbanLeaf | D13: 4 | E13: 180 | F13: =D13*E13 -> 720 | G13: =_xlfn.XLOOKUP(B13,Nursery_Inventory!B:B,Nursery_Inventory!E:E) -> Delhi | H13: =_xlfn.XLOOKUP(B13,Plant_Master!A:A,Plant_Master!B:B) -> Tulip | I13: =_xlfn.XLOOKUP(B13,Plant_Master!A:A,Plant_Master!C:C) -> Indoor | J13: =_xlfn.XLOOKUP(B13,Nursery_Inventory!B:B,Nursery_Inventory!C:C) -> 499
A14: 3308 | B14: 1222 | C14: EcoGarden | D14: 44 | E14: 411 | F14: =D14*E14 -> 18084 | G14: =_xlfn.XLOOKUP(B14,Nursery_Inventory!B:B,Nursery_Inventory!E:E) -> Delhi | H14: =_xlfn.XLOOKUP(B14,Plant_Master!A:A,Plant_Master!B:B) -> Lily | I14: =_xlfn.XLOOKUP(B14,Plant_Master!A:A,Plant_Master!C:C) -> Flower | J14: =_xlfn.XLOOKUP(B14,Nursery_Inventory!B:B,Nursery_Inventory!C:C) -> 492
A15: 3052 | B15: 1448 | C15: GreenGrow | D15: 44 | E15: 372 | F15: =D15*E15 -> 16368 | G15: ROI | H15: =_xlfn.XLOOKUP(B15,Plant_Master!A:A,Plant_Master!B:B) -> Lily | I15: =_xlfn.XLOOKUP(B15,Plant_Master!A:A,Plant_Master!C:C) -> Flower | J15: NA
A16: 3327 | B16: 1172 | C16: PlantHub | D16: 40 | E16: 477 | F16: =D16*E16 -> 19080 | G16: =_xlfn.XLOOKUP(B16,Nursery_Inventory!B:B,Nursery_Inventory!E:E) -> Chennai | H16: =_xlfn.XLOOKUP(B16,Plant_Master!A:A,Plant_Master!B:B) -> Jasmine | I16: =_xlfn.XLOOKUP(B16,Plant_Master!A:A,Plant_Master!C:C) -> Succulent | J16: =_xlfn.XLOOKUP(B16,Nursery_Inventory!B:B,Nursery_Inventory!C:C) -> 448
A17: 3459 | B17: 1246 | C17: NatureNest | D17: 40 | E17: 477 | F17: =D17*E17 -> 19080 | G17: ROI | H17: =_xlfn.XLOOKUP(B17,Plant_Master!A:A,Plant_Master!B:B) -> Orchid | I17: =_xlfn.XLOOKUP(B17,Plant_Master!A:A,Plant_Master!C:C) -> Succulent | J17: NA
A18: 3348 | B18: 1229 | C18: GreenGrow | D18: 38 | E18: 87 | F18: =D18*E18 -> 3306 | G18: =_xlfn.XLOOKUP(B18,Nursery_Inventory!B:B,Nursery_Inventory!E:E) -> Pune | H18: =_xlfn.XLOOKUP(B18,Plant_Master!A:A,Plant_Master!B:B) -> Tulip | I18: =_xlfn.XLOOKUP(B18,Plant_Master!A:A,Plant_Master!C:C) -> Flower | J18: =_xlfn.XLOOKUP(B18,Nursery_Inventory!B:B,Nursery_Inventory!C:C) -> 461
A19: 3316 | B19: 1229 | C19: EcoGarden | D19: 31 | E19: 61 | F19: =D19*E19 -> 1891 | G19: =_xlfn.XLOOKUP(B19,Nursery_Inventory!B:B,Nursery_Inventory!E:E) -> Pune | H19: =_xlfn.XLOOKUP(B19,Plant_Master!A:A,Plant_Master!B:B) -> Tulip | I19: =_xlfn.XLOOKUP(B19,Plant_Master!A:A,Plant_Master!C:C) -> Flower | J19: =_xlfn.XLOOKUP(B19,Nursery_Inventory!B:B,Nursery_Inventory!C:C) -> 461
A20: 3362 | B20: 1222 | C20: PlantHub | D20: 27 | E20: 379 | F20: =D20*E20 -> 10233 | G20: =_xlfn.XLOOKUP(B20,Nursery_Inventory!B:B,Nursery_Inventory!E:E) -> Delhi | H20: =_xlfn.XLOOKUP(B20,Plant_Master!A:A,Plant_Master!B:B) -> Lily | I20: =_xlfn.XLOOKUP(B20,Plant_Master!A:A,Plant_Master!C:C) -> Flower | J20: =_xlfn.XLOOKUP(B20,Nursery_Inventory!B:B,Nursery_Inventory!C:C) -> 492
A21: 3278 | B21: 1275 | C21: PlantHub | D21: 34 | E21: 446 | F21: =D21*E21 -> 15164 | G21: ROI | H21: =_xlfn.XLOOKUP(B21,Plant_Master!A:A,Plant_Master!B:B) -> Fern | I21: =_xlfn.XLOOKUP(B21,Plant_Master!A:A,Plant_Master!C:C) -> Flower | J21: NA
A22: 3481 | B22: 1114 | C22: PlantHub | D22: 46 | E22: 317 | F22: =D22*E22 -> 14582 | G22: ROI | H22: =_xlfn.XLOOKUP(B22,Plant_Master!A:A,Plant_Master!B:B) -> Cactus | I22: =_xlfn.XLOOKUP(B22,Plant_Master!A:A,Plant_Master!C:C) -> Flower | J22: NA
A23: 3031 | B23: 1222 | C23: NatureNest | D23: 16 | E23: 472 | F23: =D23*E23 -> 7552 | G23: =_xlfn.XLOOKUP(B23,Nursery_Inventory!B:B,Nursery_Inventory!E:E) -> Delhi | H23: =_xlfn.XLOOKUP(B23,Plant_Master!A:A,Plant_Master!B:B) -> Lily | I23: =_xlfn.XLOOKUP(B23,Plant_Master!A:A,Plant_Master!C:C) -> Flower | J23: =_xlfn.XLOOKUP(B23,Nursery_Inventory!B:B,Nursery_Inventory!C:C) -> 492
A24: 3488 | B24: 1496 | C24: GreenGrow | D24: 29 | E24: 434 | F24: =D24*E24 -> 12586 | G24: ROI | H24: =_xlfn.XLOOKUP(B24,Plant_Master!A:A,Plant_Master!B:B) -> Cactus | I24: =_xlfn.XLOOKUP(B24,Plant_Master!A:A,Plant_Master!C:C) -> Flower | J24: NA
A25: 3202 | B25: 1478 | C25: PlantHub | D25: 23 | E25: 258 | F25: =D25*E25 -> 5934 | G25: =_xlfn.XLOOKUP(B25,Nursery_Inventory!B:B,Nursery_Inventory!E:E) -> Pune | H25: =_xlfn.XLOOKUP(B25,Plant_Master!A:A,Plant_Master!B:B) -> Bamboo | I25: =_xlfn.XLOOKUP(B25,Plant_Master!A:A,Plant_Master!C:C) -> Outdoor | J25: =_xlfn.XLOOKUP(B25,Nursery_Inventory!B:B,Nursery_Inventory!C:C) -> 454
A26: 3285 | B26: 1211 | C26: EcoGarden | D26: 28 | E26: 391 | F26: =D26*E26 -> 10948 | G26: ROI | H26: =_xlfn.XLOOKUP(B26,Plant_Master!A:A,Plant_Master!B:B) -> Tulip | I26: =_xlfn.XLOOKUP(B26,Plant_Master!A:A,Plant_Master!C:C) -> Flower | J26: NA
A27: 3021 | B27: 1295 | C27: EcoGarden | D27: 44 | E27: 404 | F27: =D27*E27 -> 17776 | G27: =_xlfn.XLOOKUP(B27,Nursery_Inventory!B:B,Nursery_Inventory!E:E) -> Mumbai | H27: =_xlfn.XLOOKUP(B27,Plant_Master!A:A,Plant_Master!B:B) -> Tulip | I27: =_xlfn.XLOOKUP(B27,Plant_Master!A:A,Plant_Master!C:C) -> Medicinal | J27: =_xlfn.XLOOKUP(B27,Nursery_Inventory!B:B,Nursery_Inventory!C:C) -> 19
A28: 3085 | B28: 1124 | C28: PlantHub | D28: 44 | E28: 399 | F28: =D28*E28 -> 17556 | G28: =_xlfn.XLOOKUP(B28,Nursery_Inventory!B:B,Nursery_Inventory!E:E) -> Bangalore | H28: =_xlfn.XLOOKUP(B28,Plant_Master!A:A,Plant_Master!B:B) -> Aloe | I28: =_xlfn.XLOOKUP(B28,Plant_Master!A:A,Plant_Master!C:C) -> Indoor | J28: =_xlfn.XLOOKUP(B28,Nursery_Inventory!B:B,Nursery_Inventory!C:C) -> 447
A29: 3107 | B29: 1179 | C29: EcoGarden | D29: 36 | E29: 496 | F29: =D29*E29 -> 17856 | G29: =_xlfn.XLOOKUP(B29,Nursery_Inventory!B:B,Nursery_Inventory!E:E) -> Bangalore | H29: =_xlfn.XLOOKUP(B29,Plant_Master!A:A,Plant_Master!B:B) -> Jasmine | I29: =_xlfn.XLOOKUP(B29,Plant_Master!A:A,Plant_Master!C:C) -> Flower | J29: =_xlfn.XLOOKUP(B29,Nursery_Inventory!B:B,Nursery_Inventory!C:C) -> 435
A30: 3135 | B30: 1356 | C30: NatureNest | D30: 40 | E30: 444 | F30: =D30*E30 -> 17760 | G30: =_xlfn.XLOOKUP(B30,Nursery_Inventory!B:B,Nursery_Inventory!E:E) -> Bangalore | H30: =_xlfn.XLOOKUP(B30,Plant_Master!A:A,Plant_Master!B:B) -> Bamboo | I30: =_xlfn.XLOOKUP(B30,Plant_Master!A:A,Plant_Master!C:C) -> Indoor | J30: =_xlfn.XLOOKUP(B30,Nursery_Inventory!B:B,Nursery_Inventory!C:C) -> 409
A31: 3140 | B31: 1222 | C31: EcoGarden | D31: 14 | E31: 440 | F31: =D31*E31 -> 6160 | G31: =_xlfn.XLOOKUP(B31,Nursery_Inventory!B:B,Nursery_Inventory!E:E) -> Delhi | H31: =_xlfn.XLOOKUP(B31,Plant_Master!A:A,Plant_Master!B:B) -> Lily | I31: =_xlfn.XLOOKUP(B31,Plant_Master!A:A,Plant_Master!C:C) -> Flower | J31: =_xlfn.XLOOKUP(B31,Nursery_Inventory!B:B,Nursery_Inventory!C:C) -> 492
A32: 3405 | B32: 1222 | C32: PlantHub | D32: 8 | E32: 398 | F32: =D32*E32 -> 3184 | G32: =_xlfn.XLOOKUP(B32,Nursery_Inventory!B:B,Nursery_Inventory!E:E) -> Delhi | H32: =_xlfn.XLOOKUP(B32,Plant_Master!A:A,Plant_Master!B:B) -> Lily | I32: =_xlfn.XLOOKUP(B32,Plant_Master!A:A,Plant_Master!C:C) -> Flower | J32: =_xlfn.XLOOKUP(B32,Nursery_Inventory!B:B,Nursery_Inventory!C:C) -> 492
A33: 3407 | B33: 1020 | C33: NatureNest | D33: 35 | E33: 483 | F33: =D33*E33 -> 16905 | G33: =_xlfn.XLOOKUP(B33,Nursery_Inventory!B:B,Nursery_Inventory!E:E) -> Mumbai | H33: =_xlfn.XLOOKUP(B33,Plant_Master!A:A,Plant_Master!B:B) -> Palm | I33: =_xlfn.XLOOKUP(B33,Plant_Master!A:A,Plant_Master!C:C) -> Succulent | J33: =_xlfn.XLOOKUP(B33,Nursery_Inventory!B:B,Nursery_Inventory!C:C) -> 164
A34: 3438 | B34: 1070 | C34: UrbanLeaf | D34: 48 | E34: 435 | F34: =D34*E34 -> 20880 | G34: ROI | H34: =_xlfn.XLOOKUP(B34,Plant_Master!A:A,Plant_Master!B:B) -> Jasmine | I34: =_xlfn.XLOOKUP(B34,Plant_Master!A:A,Plant_Master!C:C) -> Outdoor | J34: NA
A35: 3058 | B35: 1385 | C35: PlantHub | D35: 47 | E35: 421 | F35: =D35*E35 -> 19787 | G35: ROI | H35: =_xlfn.XLOOKUP(B35,Plant_Master!A:A,Plant_Master!B:B) -> Jasmine | I35: =_xlfn.XLOOKUP(B35,Plant_Master!A:A,Plant_Master!C:C) -> Outdoor | J35: NA
A36: 3020 | B36: 1463 | C36: UrbanLeaf | D36: 43 | E36: 385 | F36: =D36*E36 -> 16555 | G36: =_xlfn.XLOOKUP(B36,Nursery_Inventory!B:B,Nursery_Inventory!E:E) -> Chennai | H36: =_xlfn.XLOOKUP(B36,Plant_Master!A:A,Plant_Master!B:B) -> Lily | I36: =_xlfn.XLOOKUP(B36,Plant_Master!A:A,Plant_Master!C:C) -> Succulent | J36: =_xlfn.XLOOKUP(B36,Nursery_Inventory!B:B,Nursery_Inventory!C:C) -> 382
A37: 3156 | B37: 1306 | C37: PlantHub | D37: 39 | E37: 424 | F37: =D37*E37 -> 16536 | G37: =_xlfn.XLOOKUP(B37,Nursery_Inventory!B:B,Nursery_Inventory!E:E) -> Mumbai | H37: =_xlfn.XLOOKUP(B37,Plant_Master!A:A,Plant_Master!B:B) -> Lily | I37: =_xlfn.XLOOKUP(B37,Plant_Master!A:A,Plant_Master!C:C) -> Medicinal | J37: =_xlfn.XLOOKUP(B37,Nursery_Inventory!B:B,Nursery_Inventory!C:C) -> 412
A38: 3426 | B38: 1497 | C38: PlantHub | D38: 26 | E38: 396 | F38: =D38*E38 -> 10296 | G38: ROI | H38: =_xlfn.XLOOKUP(B38,Plant_Master!A:A,Plant_Master!B:B) -> Fern | I38: =_xlfn.XLOOKUP(B38,Plant_Master!A:A,Plant_Master!C:C) -> Flower | J38: NA
A39: 3158 | B39: 1046 | C39: GreenGrow | D39: 39 | E39: 245 | F39: =D39*E39 -> 9555 | G39: ROI | H39: =_xlfn.XLOOKUP(B39,Plant_Master!A:A,Plant_Master!B:B) -> Fern | I39: =_xlfn.XLOOKUP(B39,Plant_Master!A:A,Plant_Master!C:C) -> Flower | J39: NA
A40: 3469 | B40: 1477 | C40: PlantHub | D40: 48 | E40: 76 | F40: =D40*E40 -> 3648 | G40: =_xlfn.XLOOKUP(B40,Nursery_Inventory!B:B,Nursery_Inventory!E:E) -> Bangalore | H40: =_xlfn.XLOOKUP(B40,Plant_Master!A:A,Plant_Master!B:B) -> Lily | I40: =_xlfn.XLOOKUP(B40,Plant_Master!A:A,Plant_Master!C:C) -> Succulent | J40: =_xlfn.XLOOKUP(B40,Nursery_Inventory!B:B,Nursery_Inventory!C:C) -> 398
...

Sheet DASHBOARD
